{"name": "Тест: ошибка 404 not found при передаче несуществующего login", "status": "passed", "attachments": [{"name": "log", "source": "a6d31dc0-019a-4d88-8d41-b8a03efe47ee-attachment.txt", "type": "text/plain"}], "start": 1717768239865, "stop": 1717768240145, "uuid": "384bb74f-bbed-4451-baa2-3ecbc3821cc5", "historyId": "a9cf7991ddb224a7e7cc1f9d4698f416", "testCaseId": "a9cf7991ddb224a7e7cc1f9d4698f416", "fullName": "tests.test_login_courier.TestPostLoginCourier#test_login_courier_with_non_existent_login_shows_error_404", "labels": [{"name": "parentSuite", "value": "tests"}, {"name": "suite", "value": "test_login_courier"}, {"name": "subSuite", "value": "TestPostLoginCourier"}, {"name": "host", "value": "DESKTOP-USF6L0H"}, {"name": "thread", "value": "8512-MainThread"}, {"name": "framework", "value": "pytest"}, {"name": "language", "value": "cpython3"}, {"name": "package", "value": "tests.test_login_courier"}]}