{"name": "Тест: ошибка 404 not found при передаче несуществующего login", "status": "passed", "attachments": [{"name": "log", "source": "59c8bc67-20eb-4a88-b40f-deec7fd786f0-attachment.txt", "type": "text/plain"}], "start": 1717679537580, "stop": 1717679537859, "uuid": "40072d72-9dda-4390-ad81-a3a88849b043", "historyId": "a9cf7991ddb224a7e7cc1f9d4698f416", "testCaseId": "a9cf7991ddb224a7e7cc1f9d4698f416", "fullName": "tests.test_login_courier.TestPostLoginCourier#test_login_courier_with_non_existent_login_shows_error_404", "labels": [{"name": "parentSuite", "value": "tests"}, {"name": "suite", "value": "test_login_courier"}, {"name": "subSuite", "value": "TestPostLoginCourier"}, {"name": "host", "value": "DESKTOP-USF6L0H"}, {"name": "thread", "value": "1796-MainThread"}, {"name": "framework", "value": "pytest"}, {"name": "language", "value": "cpython3"}, {"name": "package", "value": "tests.test_login_courier"}]}