{"name": "Тест: ошибка 404 not found при передаче несуществующего login", "status": "passed", "start": 1717930446023, "stop": 1717930446281, "uuid": "def69643-7034-4cf3-9d6b-e2ec61bc7547", "historyId": "a9cf7991ddb224a7e7cc1f9d4698f416", "testCaseId": "a9cf7991ddb224a7e7cc1f9d4698f416", "fullName": "tests.test_login_courier.TestPostLoginCourier#test_login_courier_with_non_existent_login_shows_error_404", "labels": [{"name": "parentSuite", "value": "tests"}, {"name": "suite", "value": "test_login_courier"}, {"name": "subSuite", "value": "TestPostLoginCourier"}, {"name": "host", "value": "DESKTOP-USF6L0H"}, {"name": "thread", "value": "16456-MainThread"}, {"name": "framework", "value": "pytest"}, {"name": "language", "value": "cpython3"}, {"name": "package", "value": "tests.test_login_courier"}]}